I'm sorry, but an uncaught exception occurred.

While running game code:
  File "game/Scripts/office.rpy", line 350, in script
    if talk_truth == True:
  File "game/Scripts/office.rpy", line 350, in <module>
    if talk_truth == True:
NameError: name 'talk_truth' is not defined

-- Full Traceback ------------------------------------------------------------

Full traceback:
  File "game/Scripts/office.rpy", line 350, in script
    if talk_truth == True:
  File "/home/dmitrii/renpy-8.2.1-sdk/renpy/ast.py", line 1842, in execute
    if renpy.python.py_eval(condition):
  File "/home/dmitrii/renpy-8.2.1-sdk/renpy/python.py", line 1209, in py_eval
    return py_eval_bytecode(code, globals, locals)
  File "/home/dmitrii/renpy-8.2.1-sdk/renpy/python.py", line 1202, in py_eval_bytecode
    return eval(bytecode, globals, locals)
  File "game/Scripts/office.rpy", line 350, in <module>
    if talk_truth == True:
NameError: name 'talk_truth' is not defined

Linux-5.15.0-71-generic-x86_64-with-glibc2.35 x86_64
Ren'Py 8.2.1.24030407
GlashaTest 1.0
Tue Apr  9 15:22:57 2024
